<?xml version="1.0" ?>
<robot
  name="engineer">
  <link
    name="base_link">
  </link>
  <link
    name="Link1">
  </link>
  <joint
    name="Joint1"
    type="revolute">
    <origin
      xyz="0.084918 -2.5632E-05 0.2789"
      rpy="0 0 0" />
    <parent
      link="base_link" />
    <child
      link="Link1" />
    <axis
      xyz="0 0 -1" />
    <limit
      lower="-3.14"
      upper="3.14"
      effort="1000"
      velocity="1000" />
  </joint>
  <link
    name="Link2">
  </link>
  <joint
    name="Joint2"
    type="revolute">
    <origin
      xyz="0 0 0"
      rpy="1.5708 -0.69813 3.1416" />
    <parent
      link="Link1" />
    <child
      link="Link2" />
    <axis
      xyz="0 0 1" />
    <limit
      lower="0"
      upper="1.74"
      effort="1000"
      velocity="1000" />
  </joint>
  <link
    name="Link3">
  </link>
  <joint
    name="Joint3"
    type="revolute">
    <origin
      xyz="0.275 0 -0.000496"
      rpy="-3.1416 0 0.87266" />
    <parent
      link="Link2" />
    <child
      link="Link3" />
    <axis
      xyz="0 0 1" />
    <limit
      lower="0.0"
      upper="1.745"
      effort="1000"
      velocity="1000" />
  </joint>
  <link
    name="Link4">
  </link>
  <joint
    name="Joint4"
    type="revolute">
    <origin
      xyz="0 -0.335 0"
      rpy="-1.5708 0 0" />
    <parent
      link="Link3" />
    <child
      link="Link4" />
    <axis
      xyz="0 0 1" />
    <limit
      lower="-2.0"
      upper="2.0"
      effort="1000"
      velocity="1000" />
  </joint>
  <link
    name="Link5">
</link>
  <joint
    name="Joint5"
    type="revolute">
    <origin
      xyz="0 0 0"
      rpy="-1.5708 0 -3.1416" />
    <parent
      link="Link4" />
    <child
      link="Link5" />
    <axis
      xyz="0 0 1" />
    <limit
      lower="0"
      upper="3.14"
      effort="1000"
      velocity="1000" />
  </joint>
  <link
    name="Link6">
  </link>
  <joint
    name="Joint6"
    type="revolute">
    <origin
      xyz="0.15 0 0"
      rpy="0 0 1.5708" />
    <parent
      link="Link5" />
    <child
      link="Link6" />
    <axis
      xyz="0 0 1" />
    <limit
      lower="-1.57"
      upper="1.57"
      effort="1000"
      velocity="1000" />
  </joint>
  <link
    name="Link7">
  </link>
  <joint
    name="Joint7"
    type="revolute">
    <origin
      xyz="0 -0.050353 0"
      rpy="1.5708 0 0" />
    <parent
      link="Link6" />
    <child
      link="Link7" />
    <axis
      xyz="0 0 1" />
    <limit
      lower="-3.14"
      upper="3.14"
      effort="1000"
      velocity="1000" />
  </joint>
</robot>